OrderBookSim/OrderBookSim/Outputs/Log1359734240.txt
0--INFO	Added rule
0--INFO	Added rule
0--INFO	Added rule
0--INFO	Added rule
0--INFO	Added trader: Trader[0]: Cash[$18353.22], Holding:GOOG[11441], PositionCash[$18353.22], PositionHolding:GOOG[11441]
0--INFO	Added trader: Trader[1]: Cash[$1240.88], Holding:GOOG[14912], PositionCash[$1240.88], PositionHolding:GOOG[14912]
0--INFO	Added trader: Trader[2]: Cash[$14644.00], Holding:GOOG[15920], PositionCash[$14644.00], PositionHolding:GOOG[15920]
0--INFO	Added trader: Trader[3]: Cash[$15648.67], Holding:GOOG[9899], PositionCash[$15648.67], PositionHolding:GOOG[9899]
0--INFO	Added trader: Trader[4]: Cash[$5468.92], Holding:GOOG[7183], PositionCash[$5468.92], PositionHolding:GOOG[7183]
0--INFO	Added trader: Trader[5]: Cash[$2301.71], Holding:GOOG[15020], PositionCash[$2301.71], PositionHolding:GOOG[15020]
0--INFO	Added trader: Trader[6]: Cash[$17365.03], Holding:GOOG[11325], PositionCash[$17365.03], PositionHolding:GOOG[11325]
0--INFO	Added trader: Trader[7]: Cash[$9956.36], Holding:GOOG[16312], PositionCash[$9956.36], PositionHolding:GOOG[16312]
0--INFO	Added trader: Trader[8]: Cash[$2255.93], Holding:GOOG[11756], PositionCash[$2255.93], PositionHolding:GOOG[11756]
0--INFO	Added trader: Trader[9]: Cash[$15930.05], Holding:GOOG[19990], PositionCash[$15930.05], PositionHolding:GOOG[19990]
0--INFO	Added trader: Trader[10]: Cash[$9361.25], Holding:GOOG[11548], PositionCash[$9361.25], PositionHolding:GOOG[11548]
0--INFO	Added trader: Trader[11]: Cash[$12101.20], Holding:GOOG[7186], PositionCash[$12101.20], PositionHolding:GOOG[7186]
0--INFO	Added trader: Trader[12]: Cash[$7014.37], Holding:GOOG[4120], PositionCash[$7014.37], PositionHolding:GOOG[4120]
0--INFO	Added trader: Trader[13]: Cash[$12181.16], Holding:GOOG[15503], PositionCash[$12181.16], PositionHolding:GOOG[15503]
0--INFO	Added trader: Trader[14]: Cash[$17079.99], Holding:GOOG[19310], PositionCash[$17079.99], PositionHolding:GOOG[19310]
0--INFO	Added trader: Trader[15]: Cash[$13667.41], Holding:GOOG[2129], PositionCash[$13667.41], PositionHolding:GOOG[2129]
0--INFO	Added trader: Trader[16]: Cash[$4786.52], Holding:GOOG[11280], PositionCash[$4786.52], PositionHolding:GOOG[11280]
0--INFO	Added trader: Trader[17]: Cash[$2618.49], Holding:GOOG[19127], PositionCash[$2618.49], PositionHolding:GOOG[19127]
0--INFO	Added trader: Trader[18]: Cash[$9226.36], Holding:GOOG[7583], PositionCash[$9226.36], PositionHolding:GOOG[7583]
0--INFO	Added trader: Trader[19]: Cash[$5058.14], Holding:GOOG[4456], PositionCash[$5058.14], PositionHolding:GOOG[4456]
0--INFO	Added trader: Trader[20]: Cash[$16802.88], Holding:GOOG[7472], PositionCash[$16802.88], PositionHolding:GOOG[7472]
0--INFO	Added trader: Trader[21]: Cash[$7907.96], Holding:GOOG[15027], PositionCash[$7907.96], PositionHolding:GOOG[15027]
0--INFO	Added trader: Trader[22]: Cash[$4198.13], Holding:GOOG[4802], PositionCash[$4198.13], PositionHolding:GOOG[4802]
0--INFO	Added trader: Trader[23]: Cash[$17402.26], Holding:GOOG[12956], PositionCash[$17402.26], PositionHolding:GOOG[12956]
0--INFO	Added trader: Trader[24]: Cash[$1361.13], Holding:GOOG[18998], PositionCash[$1361.13], PositionHolding:GOOG[18998]
0--INFO	Added trader: Trader[25]: Cash[$16390.88], Holding:GOOG[15749], PositionCash[$16390.88], PositionHolding:GOOG[15749]
0--INFO	Added trader: Trader[26]: Cash[$1141.39], Holding:GOOG[9180], PositionCash[$1141.39], PositionHolding:GOOG[9180]
0--INFO	Added trader: Trader[27]: Cash[$6382.64], Holding:GOOG[7915], PositionCash[$6382.64], PositionHolding:GOOG[7915]
0--INFO	Added trader: Trader[28]: Cash[$3039.64], Holding:GOOG[4106], PositionCash[$3039.64], PositionHolding:GOOG[4106]
0--INFO	Added trader: Trader[29]: Cash[$18004.09], Holding:GOOG[17951], PositionCash[$18004.09], PositionHolding:GOOG[17951]
0--INFO	Added trader: Trader[30]: Cash[$16526.99], Holding:GOOG[6495], PositionCash[$16526.99], PositionHolding:GOOG[6495]
0--INFO	Added trader: Trader[31]: Cash[$7350.69], Holding:GOOG[3268], PositionCash[$7350.69], PositionHolding:GOOG[3268]
0--INFO	Added trader: Trader[32]: Cash[$17095.86], Holding:GOOG[7293], PositionCash[$17095.86], PositionHolding:GOOG[7293]
0--INFO	Added trader: Trader[33]: Cash[$18353.22], Holding:GOOG[11441], PositionCash[$18353.22], PositionHolding:GOOG[11441]
0--INFO	Added trader: Trader[34]: Cash[$18353.22], Holding:GOOG[11441], PositionCash[$18353.22], PositionHolding:GOOG[11441]
0--INFO	Added trader: Trader[35]: Cash[$18353.22], Holding:GOOG[11441], PositionCash[$18353.22], PositionHolding:GOOG[11441]
0--INFO	Added trader: Trader[36]: Cash[$18353.22], Holding:GOOG[11441], PositionCash[$18353.22], PositionHolding:GOOG[11441]
0--INFO	Added trader: Trader[37]: Cash[$18353.22], Holding:GOOG[11441], PositionCash[$18353.22], PositionHolding:GOOG[11441]
0--INFO	Added trader: Trader[38]: Cash[$18353.22], Holding:GOOG[11441], PositionCash[$18353.22], PositionHolding:GOOG[11441]
0--INFO	Added trader: Trader[39]: Cash[$18353.22], Holding:GOOG[11441], PositionCash[$18353.22], PositionHolding:GOOG[11441]
0--INFO	Added trader: Trader[40]: Cash[$18353.22], Holding:GOOG[11441], PositionCash[$18353.22], PositionHolding:GOOG[11441]
0--INFO	Added trader: Trader[41]: Cash[$18353.22], Holding:GOOG[11441], PositionCash[$18353.22], PositionHolding:GOOG[11441]
0--INFO	Added trader: Trader[42]: Cash[$18353.22], Holding:GOOG[11441], PositionCash[$18353.22], PositionHolding:GOOG[11441]
0--INFO	Added trader: Trader[43]: Cash[$18353.22], Holding:GOOG[11441], PositionCash[$18353.22], PositionHolding:GOOG[11441]
0--INFO	Added trader: Trader[44]: Cash[$18353.22], Holding:GOOG[11441], PositionCash[$18353.22], PositionHolding:GOOG[11441]
0--INFO	Added trader: Trader[45]: Cash[$18353.22], Holding:GOOG[11441], PositionCash[$18353.22], PositionHolding:GOOG[11441]
0--INFO	Added trader: Trader[46]: Cash[$18353.22], Holding:GOOG[11441], PositionCash[$18353.22], PositionHolding:GOOG[11441]
0--INFO	Added trader: Trader[47]: Cash[$18353.22], Holding:GOOG[11441], PositionCash[$18353.22], PositionHolding:GOOG[11441]
0--INFO	Added trader: Trader[48]: Cash[$1000000.00], Holding:GOOG[10000000], PositionCash[$1000000.00], PositionHolding:GOOG[10000000]
0--INFO	Added trader: Trader[49]: Cash[$1000000.00], Holding:GOOG[10000000], PositionCash[$1000000.00], PositionHolding:GOOG[10000000]
42--INFO	Enqueued order: Price: 2147483647.00, Volume: 502, Type: BUY, Market Order: 1, Participant: 32, Stock:[ID: 0, Symbol: GOOG], Time: 42, OrderNumber: 0
65--INFO	Enqueued order: Price: 0.00, Volume: 733, Type: SELL, Market Order: 1, Participant: 33, Stock:[ID: 0, Symbol: GOOG], Time: 65, OrderNumber: 1
65--INFO	Enqueued order: Price: 0.93, Volume: 495, Type: BUY, Market Order: 0, Participant: 34, Stock:[ID: 0, Symbol: GOOG], Time: 65, OrderNumber: 2
65--INFO	Enqueued order: Price: 2147483647.00, Volume: 68, Type: BUY, Market Order: 1, Participant: 35, Stock:[ID: 0, Symbol: GOOG], Time: 65, OrderNumber: 3
65--INFO	Enqueued order: Price: 0.00, Volume: 869, Type: SELL, Market Order: 1, Participant: 36, Stock:[ID: 0, Symbol: GOOG], Time: 65, OrderNumber: 4
65--INFO	Enqueued order: Price: 2147483647.00, Volume: 816, Type: BUY, Market Order: 1, Participant: 37, Stock:[ID: 0, Symbol: GOOG], Time: 65, OrderNumber: 5
65--INFO	Enqueued order: Price: 1.05, Volume: 788, Type: SELL, Market Order: 0, Participant: 38, Stock:[ID: 0, Symbol: GOOG], Time: 65, OrderNumber: 6
65--INFO	Enqueued order: Price: 2147483647.00, Volume: 469, Type: BUY, Market Order: 1, Participant: 39, Stock:[ID: 0, Symbol: GOOG], Time: 65, OrderNumber: 7
65--INFO	Enqueued order: Price: 2147483647.00, Volume: 360, Type: BUY, Market Order: 1, Participant: 40, Stock:[ID: 0, Symbol: GOOG], Time: 65, OrderNumber: 8
65--INFO	Enqueued order: Price: 0.00, Volume: 241, Type: SELL, Market Order: 1, Participant: 41, Stock:[ID: 0, Symbol: GOOG], Time: 65, OrderNumber: 9
65--INFO	Enqueued order: Price: 2147483647.00, Volume: 854, Type: BUY, Market Order: 1, Participant: 42, Stock:[ID: 0, Symbol: GOOG], Time: 65, OrderNumber: 10
65--INFO	Enqueued order: Price: 2147483647.00, Volume: 107, Type: BUY, Market Order: 1, Participant: 43, Stock:[ID: 0, Symbol: GOOG], Time: 65, OrderNumber: 11
